<?xml version="1.0" encoding="UTF-8"?>
<testng-results skipped="0" failed="1" ignored="0" total="1" passed="0">
  <reporter-output>
  </reporter-output>
  <suite name="Default suite" duration-ms="4643" started-at="2020-10-11T09:40:52Z" finished-at="2020-10-11T09:40:57Z">
    <groups>
    </groups>
    <test name="Default test" duration-ms="4643" started-at="2020-10-11T09:40:52Z" finished-at="2020-10-11T09:40:57Z">
      <class name="com.lma.testScripts.LmaTestCase">
        <test-method status="PASS" signature="setup(org.testng.ITestContext)[pri:0, instance:com.lma.testScripts.LmaTestCase@689604d9]" name="setup" is-config="true" duration-ms="429" started-at="2020-10-11T09:40:52Z" finished-at="2020-10-11T09:40:53Z">
          <params>
            <param index="0">
              <value>
                <![CDATA[org.testng.TestRunner@4409e975]]>
              </value>
            </param>
          </params>
          <reporter-output>
          </reporter-output>
        </test-method> <!-- setup -->
        <test-method status="FAIL" signature="AddCounterParty()[pri:0, instance:com.lma.testScripts.LmaTestCase@689604d9]" name="AddCounterParty" duration-ms="4192" started-at="2020-10-11T09:40:53Z" finished-at="2020-10-11T09:40:57Z">
          <exception class="com.lma.utilities.MyOwnException">
            <message>
              <![CDATA[Login SUCCESSFUL
UNABLE TO INITIATE THE login PROCESS 
null
]]>
            </message>
            <full-stacktrace>
              <![CDATA[com.lma.utilities.MyOwnException: Login SUCCESSFUL
UNABLE TO INITIATE THE login PROCESS 
null

at com.lma.accelarators.Base.throwException(Base.java:213)
at com.lma.testScripts.LmaTestCase.AddCounterParty(LmaTestCase.java:40)
at sun.reflect.NativeMethodAccessorImpl.invoke0(Native Method)
at sun.reflect.NativeMethodAccessorImpl.invoke(Unknown Source)
at sun.reflect.DelegatingMethodAccessorImpl.invoke(Unknown Source)
at java.lang.reflect.Method.invoke(Unknown Source)
at org.testng.internal.MethodInvocationHelper.invokeMethod(MethodInvocationHelper.java:124)
at org.testng.internal.Invoker.invokeMethod(Invoker.java:583)
at org.testng.internal.Invoker.invokeTestMethod(Invoker.java:719)
at org.testng.internal.Invoker.invokeTestMethods(Invoker.java:989)
at org.testng.internal.TestMethodWorker.invokeTestMethods(TestMethodWorker.java:125)
at org.testng.internal.TestMethodWorker.run(TestMethodWorker.java:109)
at org.testng.TestRunner.privateRun(TestRunner.java:648)
at org.testng.TestRunner.run(TestRunner.java:505)
at org.testng.SuiteRunner.runTest(SuiteRunner.java:455)
at org.testng.SuiteRunner.runSequentially(SuiteRunner.java:450)
at org.testng.SuiteRunner.privateRun(SuiteRunner.java:415)
at org.testng.SuiteRunner.run(SuiteRunner.java:364)
at org.testng.SuiteRunnerWorker.runSuite(SuiteRunnerWorker.java:52)
at org.testng.SuiteRunnerWorker.run(SuiteRunnerWorker.java:84)
at org.testng.TestNG.runSuitesSequentially(TestNG.java:1208)
at org.testng.TestNG.runSuitesLocally(TestNG.java:1137)
at org.testng.TestNG.runSuites(TestNG.java:1049)
at org.testng.TestNG.run(TestNG.java:1017)
at org.testng.remote.AbstractRemoteTestNG.run(AbstractRemoteTestNG.java:115)
at org.testng.remote.RemoteTestNG.initAndRun(RemoteTestNG.java:251)
at org.testng.remote.RemoteTestNG.main(RemoteTestNG.java:77)
]]>
            </full-stacktrace>
          </exception> <!-- com.lma.utilities.MyOwnException -->
          <reporter-output>
          </reporter-output>
        </test-method> <!-- AddCounterParty -->
        <test-method status="FAIL" signature="afterExecutionOfEachTest(java.lang.reflect.Method, org.testng.ITestContext, org.testng.ITestResult)[pri:0, instance:com.lma.testScripts.LmaTestCase@689604d9]" name="afterExecutionOfEachTest" is-config="true" duration-ms="3" started-at="2020-10-11T09:40:57Z" finished-at="2020-10-11T09:40:57Z">
          <params>
            <param index="0">
              <value>
                <![CDATA[public void com.lma.testScripts.LmaTestCase.AddCounterParty() throws java.lang.InterruptedException,com.lma.utilities.MyOwnException]]>
              </value>
            </param>
            <param index="1">
              <value>
                <![CDATA[org.testng.TestRunner@4409e975]]>
              </value>
            </param>
            <param index="2">
              <value>
                <![CDATA[[TestResult name=AddCounterParty status=FAILURE method=LmaTestCase.AddCounterParty()[pri:0, instance:com.lma.testScripts.LmaTestCase@689604d9] output={null}]]]>
              </value>
            </param>
          </params>
          <exception class="com.lma.utilities.MyOwnException">
            <message>
              <![CDATA[AFTER METHOD IS NOT SUCCESSFUL
null]]>
            </message>
            <full-stacktrace>
              <![CDATA[com.lma.utilities.MyOwnException: AFTER METHOD IS NOT SUCCESSFUL
null
at com.lma.accelarators.Base.throwException(Base.java:213)
at com.lma.testScripts.LmaTestCase.afterExecutionOfEachTest(LmaTestCase.java:74)
at sun.reflect.NativeMethodAccessorImpl.invoke0(Native Method)
at sun.reflect.NativeMethodAccessorImpl.invoke(Unknown Source)
at sun.reflect.DelegatingMethodAccessorImpl.invoke(Unknown Source)
at java.lang.reflect.Method.invoke(Unknown Source)
at org.testng.internal.MethodInvocationHelper.invokeMethod(MethodInvocationHelper.java:124)
at org.testng.internal.MethodInvocationHelper.invokeMethodConsideringTimeout(MethodInvocationHelper.java:59)
at org.testng.internal.Invoker.invokeConfigurationMethod(Invoker.java:458)
at org.testng.internal.Invoker.invokeConfigurations(Invoker.java:222)
at org.testng.internal.Invoker.invokeMethod(Invoker.java:646)
at org.testng.internal.Invoker.invokeTestMethod(Invoker.java:719)
at org.testng.internal.Invoker.invokeTestMethods(Invoker.java:989)
at org.testng.internal.TestMethodWorker.invokeTestMethods(TestMethodWorker.java:125)
at org.testng.internal.TestMethodWorker.run(TestMethodWorker.java:109)
at org.testng.TestRunner.privateRun(TestRunner.java:648)
at org.testng.TestRunner.run(TestRunner.java:505)
at org.testng.SuiteRunner.runTest(SuiteRunner.java:455)
at org.testng.SuiteRunner.runSequentially(SuiteRunner.java:450)
at org.testng.SuiteRunner.privateRun(SuiteRunner.java:415)
at org.testng.SuiteRunner.run(SuiteRunner.java:364)
at org.testng.SuiteRunnerWorker.runSuite(SuiteRunnerWorker.java:52)
at org.testng.SuiteRunnerWorker.run(SuiteRunnerWorker.java:84)
at org.testng.TestNG.runSuitesSequentially(TestNG.java:1208)
at org.testng.TestNG.runSuitesLocally(TestNG.java:1137)
at org.testng.TestNG.runSuites(TestNG.java:1049)
at org.testng.TestNG.run(TestNG.java:1017)
at org.testng.remote.AbstractRemoteTestNG.run(AbstractRemoteTestNG.java:115)
at org.testng.remote.RemoteTestNG.initAndRun(RemoteTestNG.java:251)
at org.testng.remote.RemoteTestNG.main(RemoteTestNG.java:77)
]]>
            </full-stacktrace>
          </exception> <!-- com.lma.utilities.MyOwnException -->
          <reporter-output>
          </reporter-output>
        </test-method> <!-- afterExecutionOfEachTest -->
        <test-method status="PASS" signature="close(org.testng.ITestContext)[pri:0, instance:com.lma.testScripts.LmaTestCase@689604d9]" name="close" is-config="true" duration-ms="1" started-at="2020-10-11T09:40:57Z" finished-at="2020-10-11T09:40:57Z">
          <params>
            <param index="0">
              <value>
                <![CDATA[org.testng.TestRunner@4409e975]]>
              </value>
            </param>
          </params>
          <reporter-output>
          </reporter-output>
        </test-method> <!-- close -->
      </class> <!-- com.lma.testScripts.LmaTestCase -->
    </test> <!-- Default test -->
  </suite> <!-- Default suite -->
</testng-results>
